Python 3.5.1 (v3.5.1:37a07cee5969, Dec  6 2015, 01:38:48) [MSC v.1900 32 bit (Intel)] on win32
Type "copyright", "credits" or "license()" for more information.
>>> 
 RESTART: C:/Users/Student/AppData/Local/Programs/Python/Python35-32/Ex_Files_Python_3_EssT/Exercise Files/11 Functions/generatorCreatingSequence.py 
This is the functions.py file.
0 1 2 3 4 5 6 7 8 9 10 11 12 13 14 15 16 17 18 19 20 21 22 23 24 
>>> 
 RESTART: C:/Users/Student/AppData/Local/Programs/Python/Python35-32/Ex_Files_Python_3_EssT/Exercise Files/11 Functions/generatorCreatingSequence.py 
This is the functions.py file.
0 1 2 3 4 5 6 7 8 9 10 11 12 13 14 15 16 17 18 19 20 21 22 23 24 25 
>>> 
 RESTART: C:/Users/Student/AppData/Local/Programs/Python/Python35-32/Ex_Files_Python_3_EssT/Exercise Files/11 Functions/generatorCreatingSequence.py 
This is the functions.py file.
0 1 2 3 4 5 6 7 8 9 10 11 12 13 14 15 16 17 18 19 20 21 22 23 24 25 
>>> 
 RESTART: C:/Users/Student/AppData/Local/Programs/Python/Python35-32/Ex_Files_Python_3_EssT/Exercise Files/11 Functions/generatorCreatingSequence.py 
This is the functions.py file.
5 6 7 8 9 10 11 12 13 14 15 16 17 18 19 20 21 22 23 24 25 
>>> 
 RESTART: C:/Users/Student/AppData/Local/Programs/Python/Python35-32/Ex_Files_Python_3_EssT/Exercise Files/11 Functions/generatorCreatingSequence.py 
This is the functions.py file.
Traceback (most recent call last):
  File "C:/Users/Student/AppData/Local/Programs/Python/Python35-32/Ex_Files_Python_3_EssT/Exercise Files/11 Functions/generatorCreatingSequence.py", line 134, in <module>
    if __name__ == "__main__": main()
  File "C:/Users/Student/AppData/Local/Programs/Python/Python35-32/Ex_Files_Python_3_EssT/Exercise Files/11 Functions/generatorCreatingSequence.py", line 113, in main
    for i in inclusive_range(5, 25, 3):
  File "C:/Users/Student/AppData/Local/Programs/Python/Python35-32/Ex_Files_Python_3_EssT/Exercise Files/11 Functions/generatorCreatingSequence.py", line 127, in inclusive_range
    (start, stop, step)
UnboundLocalError: local variable 'start' referenced before assignment
>>> 
 RESTART: C:/Users/Student/AppData/Local/Programs/Python/Python35-32/Ex_Files_Python_3_EssT/Exercise Files/11 Functions/generatorCreatingSequence.py 
This is the functions.py file.
Traceback (most recent call last):
  File "C:/Users/Student/AppData/Local/Programs/Python/Python35-32/Ex_Files_Python_3_EssT/Exercise Files/11 Functions/generatorCreatingSequence.py", line 134, in <module>
    if __name__ == "__main__": main()
  File "C:/Users/Student/AppData/Local/Programs/Python/Python35-32/Ex_Files_Python_3_EssT/Exercise Files/11 Functions/generatorCreatingSequence.py", line 113, in main
    for i in inclusive_range(5, 25, 3):
  File "C:/Users/Student/AppData/Local/Programs/Python/Python35-32/Ex_Files_Python_3_EssT/Exercise Files/11 Functions/generatorCreatingSequence.py", line 127, in inclusive_range
    (start, stop, step)
UnboundLocalError: local variable 'start' referenced before assignment
>>> 
 RESTART: C:/Users/Student/AppData/Local/Programs/Python/Python35-32/Ex_Files_Python_3_EssT/Exercise Files/11 Functions/generatorCreatingSequence.py 
This is the functions.py file.
5 6 7 8 9 10 11 12 13 14 15 16 17 18 19 20 21 22 23 24 25 
>>> 
 RESTART: C:/Users/Student/AppData/Local/Programs/Python/Python35-32/Ex_Files_Python_3_EssT/Exercise Files/11 Functions/generatorCreatingSequence.py 
This is the functions.py file.
5 6 7 8 9 10 11 12 13 14 15 16 17 18 19 20 21 22 23 24 25 This is the functions.py file.
Traceback (most recent call last):
  File "C:/Users/Student/AppData/Local/Programs/Python/Python35-32/Ex_Files_Python_3_EssT/Exercise Files/11 Functions/generatorCreatingSequence.py", line 134, in <module>
    if __name__ == "__main__": main()
  File "C:/Users/Student/AppData/Local/Programs/Python/Python35-32/Ex_Files_Python_3_EssT/Exercise Files/11 Functions/generatorCreatingSequence.py", line 113, in main
    for i in inclusive_range(5, 25, 3):
  File "C:/Users/Student/AppData/Local/Programs/Python/Python35-32/Ex_Files_Python_3_EssT/Exercise Files/11 Functions/generatorCreatingSequence.py", line 127, in inclusive_range
    (start, stop, step)
UnboundLocalError: local variable 'start' referenced before assignment
>>> 
 RESTART: C:/Users/Student/AppData/Local/Programs/Python/Python35-32/Ex_Files_Python_3_EssT/Exercise Files/11 Functions/generatorCreatingSequence.py 
This is the functions.py file.
5 8 11 14 17 20 23 
>>> 
 RESTART: C:/Users/Student/AppData/Local/Programs/Python/Python35-32/Ex_Files_Python_3_EssT/Exercise Files/11 Functions/generatorCreatingSequence.py 
This is the functions.py file.
Traceback (most recent call last):
  File "C:/Users/Student/AppData/Local/Programs/Python/Python35-32/Ex_Files_Python_3_EssT/Exercise Files/11 Functions/generatorCreatingSequence.py", line 166, in <module>
    if __name__ == "__main__": main()
  File "C:/Users/Student/AppData/Local/Programs/Python/Python35-32/Ex_Files_Python_3_EssT/Exercise Files/11 Functions/generatorCreatingSequence.py", line 145, in main
    for i in inclusive_range(5, 25, 3, 42):
  File "C:/Users/Student/AppData/Local/Programs/Python/Python35-32/Ex_Files_Python_3_EssT/Exercise Files/11 Functions/generatorCreatingSequence.py", line 160, in inclusive_range
    else: raise TypeError('inclusive_range expected at most 3 arguments, got {}'.format(numargs))
TypeError: inclusive_range expected at most 3 arguments, got 4
>>> 
 RESTART: C:/Users/Student/AppData/Local/Programs/Python/Python35-32/Ex_Files_Python_3_EssT/Exercise Files/11 Functions/generatorCreatingSequence.py 
This is the functions.py file.
Traceback (most recent call last):
  File "C:/Users/Student/AppData/Local/Programs/Python/Python35-32/Ex_Files_Python_3_EssT/Exercise Files/11 Functions/generatorCreatingSequence.py", line 194, in <module>
    if __name__ == "__main__": main()
  File "C:/Users/Student/AppData/Local/Programs/Python/Python35-32/Ex_Files_Python_3_EssT/Exercise Files/11 Functions/generatorCreatingSequence.py", line 173, in main
    for i in inclusive_range():
  File "C:/Users/Student/AppData/Local/Programs/Python/Python35-32/Ex_Files_Python_3_EssT/Exercise Files/11 Functions/generatorCreatingSequence.py", line 178, in inclusive_range
    if numargs < 1: raise TypeError('requires at least one argument')
TypeError: requires at least one argument
>>> 
